        # raise class_exception(*exception_.args).with_traceback(traceback_)

        # print(class_exception)
        # print(exception_)
        # print(traceback_)
        # exception_.add_note('Minha nota')

        # return True  # Tratei a exceção
